Workbook

Sheet 支出明細
A1: 2026 | B1: 西雅圖信望愛靈糧堂支出明細(A/C #2228316051)
A2: Date | B2: Month | C2: code | D2: Description | E2: Amount | F2: 備註 | G2: Memo1 | H2: 小計 | I2: Memo2 | J2: 月份總計
A3: 46024 | B3: =MONTH(A3) -> 1 | C3: E160 | D3: =VLOOKUP(C3,code!$A$2:$H$153,2,0) -> Payroll | E3: 2000
A4: 46044 | B4: =MONTH(A4) -> 1 | C4: A160 | D4: =VLOOKUP(C4,code!$A$2:$H$153,2,0) -> Utilities/Electricity, Gas, Water, Telephone | E4: 315.61 | F4: Puget Sound
A5: 46048 | B5: =MONTH(A5) -> 1 | C5: A160 | D5: =VLOOKUP(C5,code!$A$2:$H$153,2,0) -> Utilities/Electricity, Gas, Water, Telephone | E5: 170.82 | F5: Comcast | J5: =SUM(E3:E5) -> 2486.43
A6: 46055 | B6: =MONTH(A6) -> 2 | C6: E160 | D6: =VLOOKUP(C6,code!$A$2:$H$153,2,0) -> Payroll | E6: 2000
A7: 46073 | B7: =MONTH(A7) -> 2 | C7: A160 | D7: =VLOOKUP(C7,code!$A$2:$H$153,2,0) -> Utilities/Electricity, Gas, Water, Telephone | E7: 285.69 | F7: City of Issaquah
A8: 46073 | B8: =MONTH(A8) -> 2 | C8: A160 | D8: =VLOOKUP(C8,code!$A$2:$H$153,2,0) -> Utilities/Electricity, Gas, Water, Telephone | E8: 304.21 | F8: Puget Sound
A9: 46078 | B9: =MONTH(A9) -> 2 | C9: A160 | D9: =VLOOKUP(C9,code!$A$2:$H$153,2,0) -> Utilities/Electricity, Gas, Water, Telephone | E9: 170.88 | F9: Comcast | J9: =SUM(E6:E9) -> 2760.78
A10: 46083 | B10: =MONTH(A10) -> 3 | C10: E160 | D10: =VLOOKUP(C10,code!$A$2:$H$153,2,0) -> Payroll | E10: 2000
A11: 46086 | B11: =MONTH(A11) -> 3 | C11: M190 | D11: =VLOOKUP(C11,code!$A$2:$H$153,2,0) -> Miscellaneous/Gifts, Meals, Refreshments, Postage | E11: 110.55 | F11: Check 1152
A12: 46090 | B12: =MONTH(A12) -> 3 | C12: M110 | D12: =VLOOKUP(C12,code!$A$2:$H$153,2,0) -> Supplies | E12: 21.55 | F12: Check 1155
A13: 46097 | B13: =MONTH(A13) -> 3 | C13: S150 | D13: =VLOOKUP(C13,code!$A$2:$H$153,2,0) -> Sunday Services-Honorarium Fee, Equipment, Supplies | E13: 200 | F13: Check 1154
A14: 46097 | B14: =MONTH(A14) -> 3 | C14: S150 | D14: =VLOOKUP(C14,code!$A$2:$H$153,2,0) -> Sunday Services-Honorarium Fee, Equipment, Supplies | E14: 200 | F14: Check 1151
A15: 46097 | B15: =MONTH(A15) -> 3 | C15: A160 | D15: =VLOOKUP(C15,code!$A$2:$H$153,2,0) -> Utilities/Electricity, Gas, Water, Telephone | E15: 672
A16: 46097 | B16: =MONTH(A16) -> 3 | C16: M110 | D16: =VLOOKUP(C16,code!$A$2:$H$153,2,0) -> Supplies | E16: 534.8 | F16: Check 1156
A17: 46098 | B17: =MONTH(A17) -> 3 | C17: A140 | D17: =VLOOKUP(C17,code!$A$2:$H$153,2,0) -> Facilities | E17: 21.46 | F17: Check 1157
A18: 46101 | B18: =MONTH(A18) -> 3 | C18: A160 | D18: =VLOOKUP(C18,code!$A$2:$H$153,2,0) -> Utilities/Electricity, Gas, Water, Telephone | E18: 257.13 | F18: Puget Sound
A19: 46106 | B19: =MONTH(A19) -> 3 | C19: A160 | D19: =VLOOKUP(C19,code!$A$2:$H$153,2,0) -> Utilities/Electricity, Gas, Water, Telephone | E19: 170.88 | F19: Comcast | J19: =SUM(E10:E19) -> 4188.37
A20: 46113 | B20: =MONTH(A20) -> 4 | C20: E160 | D20: =VLOOKUP(C20,code!$A$2:$H$153,2,0) -> Payroll | E20: 2000
A21: 46126 | B21: =MONTH(A21) -> 4 | C21: S190 | D21: =VLOOKUP(C21,code!$A$2:$H$153,2,0) -> Miscellaneous/Gifts, Meals, Refreshments, Postage | E21: 90 | F21: Check 1160
A22: 46126 | B22: =MONTH(A22) -> 4 | C22: S150 | D22: =VLOOKUP(C22,code!$A$2:$H$153,2,0) -> Sunday Services-Honorarium Fee, Equipment, Supplies | E22: 200 | F22: Check 1161
A23: 46126 | B23: =MONTH(A23) -> 4 | C23: S150 | D23: =VLOOKUP(C23,code!$A$2:$H$153,2,0) -> Sunday Services-Honorarium Fee, Equipment, Supplies | E23: 200 | F23: Check 1158
A24: 46127 | B24: =MONTH(A24) -> 4 | C24: S190 | D24: =VLOOKUP(C24,code!$A$2:$H$153,2,0) -> Miscellaneous/Gifts, Meals, Refreshments, Postage | E24: 240.87 | F24: Check 1159
A25: 46132 | B25: =MONTH(A25) -> 4 | C25: A160 | D25: =VLOOKUP(C25,code!$A$2:$H$153,2,0) -> Utilities/Electricity, Gas, Water, Telephone | E25: 339.05 | F25: City of Issaquah
A26: 46133 | B26: =MONTH(A26) -> 4 | C26: A160 | D26: =VLOOKUP(C26,code!$A$2:$H$153,2,0) -> Utilities/Electricity, Gas, Water, Telephone | E26: 246.6 | F26: Puget Sound
A27: 46139 | B27: =MONTH(A27) -> 4 | C27: A160 | D27: =VLOOKUP(C27,code!$A$2:$H$153,2,0) -> Utilities/Electricity, Gas, Water, Telephone | E27: 170.88 | F27: Comcast | J27: =SUM(E20:E27) -> 3487.4
A28: 46143 | B28: =MONTH(A28) -> 5 | C28: E160 | D28: =VLOOKUP(C28,code!$A$2:$H$153,2,0) -> Payroll | E28: 2000
A29: 46160 | B29: =MONTH(A29) -> 5 | C29: S190 | D29: =VLOOKUP(C29,code!$A$2:$H$153,2,0) -> Miscellaneous/Gifts, Meals, Refreshments, Postage | E29: 260.47 | F29: Check 1162
A30: 46162 | B30: =MONTH(A30) -> 5 | C30: A160 | D30: =VLOOKUP(C30,code!$A$2:$H$153,2,0) -> Utilities/Electricity, Gas, Water, Telephone | E30: 233.81 | F30: Puget Sound
A31: 46168 | B31: =MONTH(A31) -> 5 | C31: A160 | D31: =VLOOKUP(C31,code!$A$2:$H$153,2,0) -> Utilities/Electricity, Gas, Water, Telephone | E31: 170.88 | F31: Comcast | J31: =SUM(E28:E31) -> 2665.16
A32: 46174 | B32: =MONTH(A32) -> 6 | C32: E160 | D32: =VLOOKUP(C32,code!$A$2:$H$153,2,0) -> Payroll | E32: 2000
A33: 46195 | B33: =MONTH(A33) -> 6 | C33: A160 | D33: =VLOOKUP(C33,code!$A$2:$H$153,2,0) -> Utilities/Electricity, Gas, Water, Telephone | E33: 364.28 | F33: City of Issaquah
A34: 46195 | B34: =MONTH(A34) -> 6 | C34: A160 | D34: =VLOOKUP(C34,code!$A$2:$H$153,2,0) -> Utilities/Electricity, Gas, Water, Telephone | E34: 211.84 | F34: Puget Sound
A35: 46198 | B35: =MONTH(A35) -> 6 | C35: A160 | D35: =VLOOKUP(C35,code!$A$2:$H$153,2,0) -> Utilities/Electricity, Gas, Water, Telephone | E35: 170.88 | F35: Comcast
A36: 46203 | B36: =MONTH(A36) -> 6 | C36: A160 | D36: =VLOOKUP(C36,code!$A$2:$H$153,2,0) -> Utilities/Electricity, Gas, Water, Telephone | E36: 682.39 | F36: Cm Select Insura | J36: =SUM(E32:E36) -> 3429.39
A37: 46152 | B37: =MONTH(A37) -> 5 | D37: =VLOOKUP(C37,code!$A$2:$H$153,2,0) -> #N/A
A38: 46098 | B38: =MONTH(A38) -> 3 | D38: =VLOOKUP(C38,code!$A$2:$H$153,2,0) -> #N/A
A39: 46098 | B39: =MONTH(A39) -> 3 | D39: =VLOOKUP(C39,code!$A$2:$H$153,2,0) -> #N/A
A40: 46098 | B40: =MONTH(A40) -> 3 | D40: =VLOOKUP(C40,code!$A$2:$H$153,2,0) -> #N/A
...

Sheet 樞紐分析表
B1: 2026年 | C1: 各月支出彙總
D2: 一月份 | E2: 二月份 | F2: 三月份 | G2: 四月份 | H2: 五月份 | I2: 六月份 | K2: 五月份 | L2: 五月份 | M2: 五月份 | N2: 五月份
B4: 加總 - Amount | D4: 欄標籤
B5: 列標籤 | C5: Description | D5: 1 | E5: 2 | F5: 3 | G5: 4 | H5: 5 | I5: 6 | J5: 總計
B6: A160 | C6: Utilities/Electricity, Gas, Water, Telephone | D6: 486.43 | E6: 760.78 | F6: 1100.01 | G6: 756.53 | H6: 404.69 | I6: 1429.39 | J6: 4937.83
B7: E160 | C7: Payroll | D7: 2000 | E7: 2000 | F7: 2000 | G7: 2000 | H7: 2000 | I7: 2000 | J7: 12000
B8: M190 | C8: Miscellaneous/Gifts, Meals, Refreshments, Postage | F8: 110.55 | J8: 110.55
B9: M110 | C9: Supplies | F9: 556.35 | J9: 556.35
B10: S150 | C10: Sunday Services-Honorarium Fee, Equipment, Supplies | F10: 400 | G10: 400 | J10: 800
B11: A140 | C11: Facilities | F11: 21.46 | J11: 21.46
B12: S190 | C12: Miscellaneous/Gifts, Meals, Refreshments, Postage | G12: 330.87 | H12: 260.47 | J12: 591.34
B13: 總計 | D13: 2486.43 | E13: 2760.78 | F13: 4188.37 | G13: 3487.4 | H13: 2665.16 | I13: 3429.39 | J13: 19017.53

Sheet code
A1: co | B1: Description | H1: Remark
A2: A10- | B2: Administration, Maintenance, Facility, Office Expenses, Building Fund 行政、總務、堂務、辦公室、雜支、網站、視音
A3: A100 | B3: Equipment/Hardware, Software | H3: Asset
A4: A110 | B4: Supplies/Utensil,
A5: A120 | B5: Trainings & Meetings
A6: A130 | B6: Business Travels & Expenses
A7: A140 | B7: Facilities
A8: A150 | B8: Maintenance/Cleaning
A9: A160 | B9: Utilities/Electricity, Gas, Water, Telephone
A10: A170 | B10: Security/Safety
A11: A180 | B11: Website
A12: A190 | B12: Miscellaneous/Gifts, Meals, Refreshments, Postage
B14: Total | C14: =SUM(C3:C13) -> 0 | D14: =SUM(D3:D13) -> 0 | E14: =SUM(E3:E13) -> 0
A15: C10- | B15: Community Service, Holiday Celebration, Mercy Act 社區關懷、慈惠救助、慈惠基金、關訪交通及慶典活動
A16: C100 | B16: Equipment/Hardware, Software | H16: Asset
A17: C110 | B17: Supplies
A18: C120 | B18: Trainings & Meetings
A19: C130 | B19: Business Travels & Expenses
A20: C140 | B20: Facilities
A21: C150 | B21: Transportation/Payment, Gas, Maintenance, Insurance
A22: C160 | B22: Community Service-Seminar, Activity, Funeral, Wedding
A23: C170 | B23: Mercy Fund
A24: C180 | B24: Promotional/Ad, Sign, Tape, CD, DVD, Stripe, Bible
A25: C190 | B25: Miscellaneous/Gifts, Meals, Refreshments, Postage
B27: Total | C27: =SUM(C16:C26) -> 0 | D27: =SUM(D16:D26) -> 0 | E27: =SUM(E16:E26) -> 0
A28: E10- | B28: Ministry, Finance, Payroll, Benefit, License, Insurance 事工需要、財務稅務、薪資福利、執照保險
A29: E100 | B29: Equipment/Hardware, software | H29: Asset
A30: E110 | B30: Supplies
A31: E120 | B31: Trainings & Meetings
A32: E130 | B32: Business Travels & Expenses
A33: E140 | B33: Church Planting
A34: E150 | B34: Tax
A35: E160 | B35: Payroll
A36: E170 | B36: Benefits(Housing Allowance, Health Insurance, etc)
A37: E180 | B37: Licensing, Insurance, Worker Comp,
A38: E190 | B38: Miscellaneous/Gifts, Meals, Refreshments, Postage
B40: Total | C40: =SUM(C29:C39) -> 0 | D40: =SUM(D29:D39) -> 0 | E40: =SUM(E29:E39) -> 0
A41: F10- | B41: Functional District 功能性小組
A42: F100 | B42: Youth Group-Equipment, Supplies, Expenses
A43: F110 | B43: Caleb Group-Equipment, Supplies, Expenses
...

Sheet 各月累計支出
B1: 2026信望愛各月份 支出彙總
D2: 一月份 | E2: 二月份 | F2: 三月份 | G2: 四月份 | H2: 五月份 | I2: 六月份 | J2: 七月份 | K2: 八月份 | L2: 九月份 | M2: 十月份 | N2: 十一月份
B3: 加總 - Amount | D3: 欄標籤
B4: 列標籤 | C4: Description | D4: 1 | E4: 2 | F4: 3 | G4: 4 | H4: 5 | I4: 6 | J4: 總計
B5: A160 | C5: Utilities/Electricity, Gas, Water, Telephone | D5: 486.43 | E5: 760.78 | F5: 1100.01 | G5: 756.53 | H5: 404.69 | I5: 1429.39 | J5: 4937.83
B6: E160 | C6: Payroll | D6: 2000 | E6: 2000 | F6: 2000 | G6: 2000 | H6: 2000 | I6: 2000 | J6: 12000
B7: M190 | C7: Miscellaneous/Gifts, Meals, Refreshments, Postage | F7: 110.55 | J7: 110.55
B8: S150 | C8: Sunday Services-Honorarium Fee, Equipment, Supplies | F8: 400 | G8: 400 | J8: 800
B9: S190 | C9: Miscellaneous/Gifts, Meals, Refreshments, Postage | G9: 330.87 | H9: 260.47 | J9: 591.34
B10: M110 | C10: Supplies | F10: 556.35 | J10: 556.35
B11: A140 | C11: Facilities | F11: 21.46 | J11: 21.46
B12: 總計 | D12: 2486.43 | E12: 2760.78 | F12: 4188.37 | G12: 3487.4 | H12: 2665.16 | I12: 3429.39 | J12: 19017.53
M45: 十月份實際支出
M46: $16625.85與BK Stmt相符
M47: 但有收到美沂還款$2500

Sheet Memo
B1: Mark Code 及 Description
B2: 右鍵
B3: 欄位設定
B5: 版面配置與列印
B7: 以列表方式顯示項目標籤
B8: 取消"小計"
