Workbook

Sheet 奉獻明細
A1: 2026 | D1: 信望愛
A3: 奉獻日 | B3: 月份 | C3: 週次 | D3: 姓名編號 | E3: 姓名 | F3: 奉獻項目編號 | G3: 奉獻項目 | H3: 開立支票銀行 | I3: 支票號 | J3: 奉獻金額 | K3: 存入日期 | L3: 存入金額 | M3: 各月總計 | O3: BK Statement deposit date
A4: 46026 | B4: =MONTH(A4) -> 1 | C4: =WEEKNUM(A4) -> 2 | D4: 17 | E4: =VLOOKUP(D4,姓名檔!$A$2:$G$159,4,0) -> YU Ching Cheung天香/張譽馨 | F4: a | G4: =VLOOKUP(F4,姓名檔!$H$3:$I$11,2) -> 主日奉獻 | J4: 172
A5: 46026 | B5: =MONTH(A5) -> 1 | C5: =WEEKNUM(A5) -> 2 | D5: 9 | E5: =VLOOKUP(D5,姓名檔!$A$2:$G$159,4,0) -> Min Deng鄧敏 Sandy | F5: a | G5: =VLOOKUP(F5,姓名檔!$H$3:$I$11,2) -> 主日奉獻 | J5: 20
A6: 46026 | B6: =MONTH(A6) -> 1 | C6: =WEEKNUM(A6) -> 2 | D6: 20 | E6: =VLOOKUP(D6,姓名檔!$A$2:$G$159,4,0) -> 不具名 | F6: a | G6: =VLOOKUP(F6,姓名檔!$H$3:$I$11,2) -> 主日奉獻 | H6: =VLOOKUP(D6,姓名檔!$A$2:G$159,5,0) -> 0 | J6: 162
A7: 46026 | B7: =MONTH(A7) -> 1 | C7: =WEEKNUM(A7) -> 2 | D7: 41 | E7: =VLOOKUP(D7,姓名檔!$A$2:$G$159,4,0) -> 王思旭 Sixu Wang(王悅玲) | F7: a | G7: =VLOOKUP(F7,姓名檔!$H$3:$I$11,2) -> 主日奉獻 | H7: =VLOOKUP(D7,姓名檔!$A$2:G$159,5,0) -> Bank of America | I7: 1373 | J7: 100 | K7: 46028 | L7: =SUM(J4:J7) -> 454
A8: 46033 | B8: =MONTH(A8) -> 1 | C8: =WEEKNUM(A8) -> 3 | D8: 45 | E8: =VLOOKUP(D8,姓名檔!$A$2:$G$159,4,0) -> Dong Fang Li李東方 | F8: a | G8: =VLOOKUP(F8,姓名檔!$H$3:$I$11,2) -> 主日奉獻 | H8: =VLOOKUP(D8,姓名檔!$A$2:G$159,5,0) -> 0 | J8: 10
A9: 46033 | B9: =MONTH(A9) -> 1 | C9: =WEEKNUM(A9) -> 3 | D9: 20 | E9: =VLOOKUP(D9,姓名檔!$A$2:$G$159,4,0) -> 不具名 | F9: a | G9: =VLOOKUP(F9,姓名檔!$H$3:$I$11,2) -> 主日奉獻 | H9: =VLOOKUP(D9,姓名檔!$A$2:G$159,5,0) -> 0 | J9: 43
A10: 46033 | B10: =MONTH(A10) -> 1 | C10: =WEEKNUM(A10) -> 3 | D10: 41 | E10: =VLOOKUP(D10,姓名檔!$A$2:$G$159,4,0) -> 王思旭 Sixu Wang(王悅玲) | F10: a | G10: =VLOOKUP(F10,姓名檔!$H$3:$I$11,2) -> 主日奉獻 | H10: =VLOOKUP(D10,姓名檔!$A$2:G$159,5,0) -> Bank of America | I10: 1347 | J10: 100
A11: 46033 | B11: =MONTH(A11) -> 1 | C11: =WEEKNUM(A11) -> 3 | D11: 18 | E11: =VLOOKUP(D11,姓名檔!$A$2:$G$159,4,0) -> Yan Cheng程雁 | F11: a | G11: =VLOOKUP(F11,姓名檔!$H$3:$I$11,2) -> 主日奉獻 | H11: =VLOOKUP(D11,姓名檔!$A$2:G$159,5,0) -> Bank of America | I11: 325 | J11: 500
A12: 46033 | B12: =MONTH(A12) -> 1 | C12: =WEEKNUM(A12) -> 3 | D12: 11 | E12: =VLOOKUP(D12,姓名檔!$A$2:$G$159,4,0) -> Yu Mei Feng馮俞梅 | F12: a | G12: =VLOOKUP(F12,姓名檔!$H$3:$I$11,2) -> 主日奉獻 | H12: =VLOOKUP(D12,姓名檔!$A$2:G$159,5,0) -> Bank of America | I12: 1776 | J12: 100
A13: 46033 | B13: =MONTH(A13) -> 1 | C13: =WEEKNUM(A13) -> 3 | D13: 8 | E13: =VLOOKUP(D13,姓名檔!$A$2:$G$159,4,0) -> Christopher Liu Pamela Yu Liu | F13: a | G13: =VLOOKUP(F13,姓名檔!$H$3:$I$11,2) -> 主日奉獻 | H13: =VLOOKUP(D13,姓名檔!$A$2:G$159,5,0) -> Bank of America | I13: 5524 | J13: 200 | K13: 46036 | L13: =SUM(J8:J13) -> 953
A14: 46033 | B14: =MONTH(A14) -> 1 | C14: =WEEKNUM(A14) -> 3 | D14: 20 | E14: =VLOOKUP(D14,姓名檔!$A$2:$G$159,4,0) -> 不具名 | F14: a | G14: =VLOOKUP(F14,姓名檔!$H$3:$I$11,2) -> 主日奉獻 | H14: 人民幣 ¥8 | J14: 1.07 | K14: 46036 | L14: =J14 -> 1.07
A15: 46040 | B15: =MONTH(A15) -> 1 | C15: =WEEKNUM(A15) -> 4 | D15: 120 | E15: Xing Chen Lu-Michell | F15: a | G15: =VLOOKUP(F15,姓名檔!$H$3:$I$11,2) -> 主日奉獻 | H15: =VLOOKUP(D15,姓名檔!$A$2:G$159,5,0) -> 0 | J15: 100
A16: 46040 | B16: =MONTH(A16) -> 1 | C16: =WEEKNUM(A16) -> 4 | D16: 27 | E16: =VLOOKUP(D16,姓名檔!$A$2:$G$159,4,0) -> Sylvia Fine小元Charles | F16: a | G16: =VLOOKUP(F16,姓名檔!$H$3:$I$11,2) -> 主日奉獻 | J16: 50
A17: 46040 | B17: =MONTH(A17) -> 1 | C17: =WEEKNUM(A17) -> 4 | D17: 20 | E17: =VLOOKUP(D17,姓名檔!$A$2:$G$159,4,0) -> 不具名 | F17: b | G17: =VLOOKUP(F17,姓名檔!$H$3:$I$11,2) -> 什一奉獻 | H17: 不願留名女士奉獻 | J17: 2000
A18: 46040 | B18: =MONTH(A18) -> 1 | C18: =WEEKNUM(A18) -> 4 | D18: 17 | E18: =VLOOKUP(D18,姓名檔!$A$2:$G$159,4,0) -> YU Ching Cheung天香/張譽馨 | F18: a | G18: =VLOOKUP(F18,姓名檔!$H$3:$I$11,2) -> 主日奉獻 | H18: =VLOOKUP(D18,姓名檔!$A$2:G$159,5,0) -> 0 | J18: 100
A19: 46040 | B19: =MONTH(A19) -> 1 | C19: =WEEKNUM(A19) -> 4 | D19: 45 | E19: =VLOOKUP(D19,姓名檔!$A$2:$G$159,4,0) -> Dong Fang Li李東方 | F19: a | G19: =VLOOKUP(F19,姓名檔!$H$3:$I$11,2) -> 主日奉獻 | H19: =VLOOKUP(D19,姓名檔!$A$2:G$159,5,0) -> 0 | J19: 10
A20: 46040 | B20: =MONTH(A20) -> 1 | C20: =WEEKNUM(A20) -> 4 | D20: 20 | E20: =VLOOKUP(D20,姓名檔!$A$2:$G$159,4,0) -> 不具名 | F20: a | G20: =VLOOKUP(F20,姓名檔!$H$3:$I$11,2) -> 主日奉獻 | H20: =VLOOKUP(D20,姓名檔!$A$2:G$159,5,0) -> 0 | J20: 9
A21: 46040 | B21: =MONTH(A21) -> 1 | C21: =WEEKNUM(A21) -> 4 | D21: 11 | E21: =VLOOKUP(D21,姓名檔!$A$2:$G$159,4,0) -> Yu Mei Feng馮俞梅 | F21: a | G21: =VLOOKUP(F21,姓名檔!$H$3:$I$11,2) -> 主日奉獻 | H21: =VLOOKUP(D21,姓名檔!$A$2:G$159,5,0) -> Bank of America | I21: 1777 | J21: 200
A22: 46040 | B22: =MONTH(A22) -> 1 | C22: =WEEKNUM(A22) -> 4 | D22: 8 | E22: =VLOOKUP(D22,姓名檔!$A$2:$G$159,4,0) -> Christopher Liu Pamela Yu Liu | F22: a | G22: =VLOOKUP(F22,姓名檔!$H$3:$I$11,2) -> 主日奉獻 | H22: =VLOOKUP(D22,姓名檔!$A$2:G$159,5,0) -> Bank of America | I22: 5525 | J22: 200
A23: 46040 | B23: =MONTH(A23) -> 1 | C23: =WEEKNUM(A23) -> 4 | D23: 41 | E23: =VLOOKUP(D23,姓名檔!$A$2:$G$159,4,0) -> 王思旭 Sixu Wang(王悅玲) | F23: a | G23: =VLOOKUP(F23,姓名檔!$H$3:$I$11,2) -> 主日奉獻 | H23: =VLOOKUP(D23,姓名檔!$A$2:G$159,5,0) -> Bank of America | I23: 1348 | J23: 100
A24: 46040 | B24: =MONTH(A24) -> 1 | C24: =WEEKNUM(A24) -> 4 | D24: 10 | E24: =VLOOKUP(D24,姓名檔!$A$2:$G$159,4,0) -> Yu Y Kang, Lie Chang Zhu | F24: a | G24: =VLOOKUP(F24,姓名檔!$H$3:$I$11,2) -> 主日奉獻 | H24: =VLOOKUP(D24,姓名檔!$A$2:G$159,5,0) -> Bank of America | I24: 135 | J24: 100 | K24: 46043 | L24: =SUM(J15:J24) -> 2869
A25: 46047 | B25: =MONTH(A25) -> 1 | C25: =WEEKNUM(A25) -> 5 | D25: 45 | E25: =VLOOKUP(D25,姓名檔!$A$2:$G$159,4,0) -> Dong Fang Li李東方 | F25: a | G25: =VLOOKUP(F25,姓名檔!$H$3:$I$11,2) -> 主日奉獻 | H25: =VLOOKUP(D25,姓名檔!$A$2:G$159,5,0) -> 0 | J25: 10
A26: 46047 | B26: =MONTH(A26) -> 1 | C26: =WEEKNUM(A26) -> 5 | D26: 9 | E26: =VLOOKUP(D26,姓名檔!$A$2:$G$159,4,0) -> Min Deng鄧敏 Sandy | F26: a | G26: =VLOOKUP(F26,姓名檔!$H$3:$I$11,2) -> 主日奉獻 | J26: 20
A27: 46047 | B27: =MONTH(A27) -> 1 | C27: =WEEKNUM(A27) -> 5 | D27: 20 | E27: =VLOOKUP(D27,姓名檔!$A$2:$G$159,4,0) -> 不具名 | F27: a | G27: =VLOOKUP(F27,姓名檔!$H$3:$I$11,2) -> 主日奉獻 | H27: =VLOOKUP(D27,姓名檔!$A$2:G$159,5,0) -> 0 | J27: 323
A28: 46047 | B28: =MONTH(A28) -> 1 | C28: =WEEKNUM(A28) -> 5 | D28: 41 | E28: =VLOOKUP(D28,姓名檔!$A$2:$G$159,4,0) -> 王思旭 Sixu Wang(王悅玲) | F28: a | G28: =VLOOKUP(F28,姓名檔!$H$3:$I$18,2) -> 主日奉獻 | H28: Chase | I28: 1349 | J28: 100
A29: 46047 | B29: =MONTH(A29) -> 1 | C29: =WEEKNUM(A29) -> 5 | D29: 13 | E29: =VLOOKUP(D29,姓名檔!$A$2:$G$159,4,0) -> Ed &Allison Lee | F29: a | G29: =VLOOKUP(F29,姓名檔!$H$3:$I$18,2) -> 主日奉獻 | H29: =VLOOKUP(D29,姓名檔!$A$2:G$159,5,0) -> US Bank | I29: 9844 | J29: 100 | M29: 一月份奉獻
A30: 46047 | B30: =MONTH(A30) -> 1 | C30: =WEEKNUM(A30) -> 5 | D30: 18 | E30: =VLOOKUP(D30,姓名檔!$A$2:$G$159,4,0) -> Yan Cheng程雁 | F30: a | G30: =VLOOKUP(F30,姓名檔!$H$3:$I$18,2) -> 主日奉獻 | H30: =VLOOKUP(D30,姓名檔!$A$2:G$159,5,0) -> Bank of America | I30: 154 | J30: 100 | K30: 46050 | L30: =SUM(J25:J30) -> 653 | M30: =SUM(L7:L30) -> 4930.07 | N30: 與BK STMT符
A31: 46054 | B31: =MONTH(A31) -> 2 | C31: =WEEKNUM(A31) -> 6 | D31: 9 | E31: =VLOOKUP(D31,姓名檔!$A$2:$G$159,4,0) -> Min Deng鄧敏 Sandy | F31: a | G31: =VLOOKUP(F31,姓名檔!$H$3:$I$18,2) -> 主日奉獻 | J31: 20
A32: 46054 | B32: =MONTH(A32) -> 2 | C32: =WEEKNUM(A32) -> 6 | D32: 12 | E32: =VLOOKUP(D32,姓名檔!$A$2:$G$159,4,0) -> Yu Hui Zhao趙宇輝 Yu Fei | F32: a | G32: =VLOOKUP(F32,姓名檔!$H$3:$I$18,2) -> 主日奉獻 | J32: 100
A33: 46054 | B33: =MONTH(A33) -> 2 | C33: =WEEKNUM(A33) -> 6 | D33: 20 | E33: =VLOOKUP(D33,姓名檔!$A$2:$G$159,4,0) -> 不具名 | F33: a | G33: =VLOOKUP(F33,姓名檔!$H$3:$I$18,2) -> 主日奉獻 | H33: =VLOOKUP(D33,姓名檔!$A$2:G$159,5,0) -> 0 | J33: 32
A34: 46054 | B34: =MONTH(A34) -> 2 | C34: =WEEKNUM(A34) -> 6 | D34: 41 | E34: =VLOOKUP(D34,姓名檔!$A$2:$G$159,4,0) -> 王思旭 Sixu Wang(王悅玲) | F34: a | G34: =VLOOKUP(F34,姓名檔!$H$3:$I$18,2) -> 主日奉獻 | H34: =VLOOKUP(D34,姓名檔!$A$2:G$159,5,0) -> Bank of America | I34: 1350 | J34: 100
A35: 46054 | B35: =MONTH(A35) -> 2 | C35: =WEEKNUM(A35) -> 6 | D35: 8 | E35: =VLOOKUP(D35,姓名檔!$A$2:$G$159,4,0) -> Christopher Liu Pamela Yu Liu | F35: a | G35: =VLOOKUP(F35,姓名檔!$H$3:$I$18,2) -> 主日奉獻 | H35: =VLOOKUP(D35,姓名檔!$A$2:G$159,5,0) -> Bank of America | I35: 5526 | J35: 200
A36: 46054 | B36: =MONTH(A36) -> 2 | C36: =WEEKNUM(A36) -> 6 | D36: 13 | E36: =VLOOKUP(D36,姓名檔!$A$2:$G$159,4,0) -> Ed &Allison Lee | F36: a | G36: =VLOOKUP(F36,姓名檔!$H$3:$I$18,2) -> 主日奉獻 | H36: =VLOOKUP(D36,姓名檔!$A$2:G$159,5,0) -> US Bank | I36: 9821 | J36: 100
A37: 46054 | B37: =MONTH(A37) -> 2 | C37: =WEEKNUM(A37) -> 6 | D37: 18 | E37: =VLOOKUP(D37,姓名檔!$A$2:$G$159,4,0) -> Yan Cheng程雁 | F37: a | G37: =VLOOKUP(F37,姓名檔!$H$3:$I$18,2) -> 主日奉獻 | H37: =VLOOKUP(D37,姓名檔!$A$2:G$159,5,0) -> Bank of America | I37: 455 | J37: 500 | K37: 46057 | L37: =SUM(J31:J37) -> 1052 | M37: v
A38: 46061 | B38: =MONTH(A38) -> 2 | C38: =WEEKNUM(A38) -> 7 | D38: 20 | E38: =VLOOKUP(D38,姓名檔!$A$2:$G$159,4,0) -> 不具名 | F38: a | G38: =VLOOKUP(F38,姓名檔!$H$3:$I$18,2) -> 主日奉獻 | H38: =VLOOKUP(D38,姓名檔!$A$2:G$159,5,0) -> 0 | J38: 29
A39: 46061 | B39: =MONTH(A39) -> 2 | C39: =WEEKNUM(A39) -> 7 | D39: 11 | E39: =VLOOKUP(D39,姓名檔!$A$2:$G$159,4,0) -> Yu Mei Feng馮俞梅 | F39: a | G39: =VLOOKUP(F39,姓名檔!$H$3:$I$18,2) -> 主日奉獻 | H39: =VLOOKUP(D39,姓名檔!$A$2:G$159,5,0) -> Bank of America | I39: 1778 | J39: 200
A40: 46061 | B40: =MONTH(A40) -> 2 | C40: =WEEKNUM(A40) -> 7 | D40: 41 | E40: =VLOOKUP(D40,姓名檔!$A$2:$G$159,4,0) -> 王思旭 Sixu Wang(王悅玲) | F40: a | G40: =VLOOKUP(F40,姓名檔!$H$3:$I$18,2) -> 主日奉獻 | H40: =VLOOKUP(D40,姓名檔!$A$2:G$159,5,0) -> Bank of America | I40: 1351 | J40: 100
A41: 46061 | B41: =MONTH(A41) -> 2 | C41: =WEEKNUM(A41) -> 7 | D41: 8 | E41: =VLOOKUP(D41,姓名檔!$A$2:$G$159,4,0) -> Christopher Liu Pamela Yu Liu | F41: a | G41: =VLOOKUP(F41,姓名檔!$H$3:$I$18,2) -> 主日奉獻 | H41: =VLOOKUP(D41,姓名檔!$A$2:G$159,5,0) -> Bank of America | I41: 5527 | J41: 200
...

Sheet 姓名檔
A2: 編號1 | B2: 編號2 | C2: 姓 | D2: 姓名 | E2: Bank | F2: 備註-1 | G2: 備註-2 | H2: 奉獻項目編號 | I2: 奉獻項目 | K2: 其他 | L2: 其他
A3: 1 | B3: 1 | C3: 余 | D3: 余牧師&琳玲 | E3: T.RowePrice | H3: a | I3: 主日奉獻 | K3: 120
A4: 2 | B4: 2 | C4: 喬 | D4: 喬阿姨Yen Pin Liu Chiao | E4: Chase | H4: b | I4: 什一奉獻 | L4: Gui Ba Chai
A5: 3 | B5: 3 | C5: 方 | D5: 竹英 | H5: c | I5: 感恩奉獻 | L5: Stephen & Hsin-Ju Shih(Amy)
A6: 4 | B6: 4 | C6: x | D6: x | E6: x | H6: d | I6: 建堂奉獻 | L6: Oj Qin Pan(QQ Healing Message)
A7: 5 | B7: 5 | C7: Lin | D7: WenQing Wendy Qi &Peng Paul Lin | E7: Fidelity | H7: e | I7: 其他奉獻 | L7: Irene Tentity
A8: 6 | B8: 6 | C8: Wu | D8: Joseph Wu&Mei Chen | E8: Fidelity | H8: f | I8: 宣教奉獻 | L8: Ida Siu(蕭太)
A9: 7 | B9: 7 | C9: 林 | D9: 林敏雄Mr.&Mrs. Min-Shyong Lin | E9: Fidelity | F9: 10514 206th Ave. NE Redmond.WA. 98053 | G9: 一季一次基金會開收據 | H9: g | L9: Lingeng Yuan袁林庚Jack
A10: 8 | B10: 8 | C10: Liu | D10: Christopher Liu Pamela Yu Liu | E10: Bank of America | H10: h | L10: Stephen & Hsin-Ju Shih(Amy)
A11: 9 | B11: 9 | C11: Deng | D11: Min Deng鄧敏 Sandy | E11: Wells Fargo | H11: i | I11: 代收奉獻 | L11: Fu Ching Liu劉富敬牧師
A12: 10 | B12: 10 | C12: Yu | D12: Yu Y Kang, Lie Chang Zhu | E12: Bank of America | H12: j | I12: 其他收入 | L12: Stephanie Tsai
A13: 11 | B13: 11 | C13: Feng | D13: Yu Mei Feng馮俞梅 | E13: Bank of America | F13: Toni Chen | L13: Curtis and Charlene
A14: 12 | B14: 12 | C14: Zhao | D14: Yu Hui Zhao趙宇輝 Yu Fei | E14: East West Bank | L14: Hong Wang 王宏(若琴)
A15: 13 | B15: 13 | C15: Lee | D15: Ed &Allison Lee | E15: US Bank | L15: 何馨
A16: 14 | B16: 14 | C16: x | D16: x | L16: 何海云
A17: 15 | B17: 15 | C17: Chan | D17: Ngok Chan | E17: BECU | L17: Stephanie Tsai
A18: 16 | B18: 16-1 | C18: 楊 | D18: Yuelong Jiang蔣躍龍 楊茹 | E18: Bank of America | L18: Stephen & Hsin-Ju Shih(Amy)
A19: 16-2 | B19: 16-2 | D19: Yu Sophie Yang | F19: 母:Y.J Sophie Yang | L19: Hong Wang
A20: 17 | B20: 17-1 | C20: Cheung | D20: YU Ching Cheung天香/張譽馨 | F20: 女:劉珈因 | L20: Quo Fang Shi
A21: 17-2 | B21: 17-2 | D21: 劉珈因Lau Ka Yan(Renee) | L21: Yvonne L Waver
A22: 18 | B22: 18 | C22: Cheng | D22: Yan Cheng程雁 | E22: Bank of America | F22: East West Bank | G22: Chase | L22: Li Yang 劉勇
A23: 19 | B23: 19 | C23: Chui | D23: Frank T. Chui | L23: Lie Chang Zhu
A24: 20 | B24: 20 | C24: 不具名 | D24: 不具名 | L24: Si Qi Wang
A25: 120 | B25: 120 | C25: 其他 | D25: 其他 | L25: 吳小紅
A26: 21 | B26: 21 | C26: Healing Room | D26: Healing Room | E26: Key Bank | L26: Xing Chen Lu-Michell
A27: 22 | B27: 22-1 | C27: 黃 | D27: 黃影芳老師Ying Fing Huang | E27: US Bank | F27: Ying Fing Huang22932 SE 43rd Pl Sammamish Wa 98075
A28: 22 | B28: 22-2 | C28: 崔 | D28: Li Lei Cui 崔立磊
A29: 23 | B29: 23 | C29: Liu | D29: Charles C Liu | E29: Wells Fargo
A30: 24 | B30: 24 | C30: x | D30: x
A31: 25 | B31: 25 | C31: Hu胡 | D31: 胡穎Hu Ying | E31: First Tech
A32: 26 | B32: 26 | C32: Yeh | D32: Yvonne Chi-Ping Lan & Ming Lei Yeh | E32: Bank of America | G32: Yvonne 葉明磊
A33: 27 | B33: 27 | C33: Fine | D33: Sylvia Fine小元Charles | E33: Wells Fargo | F33: 小元 | H33: BECU
A34: 28 | B34: 28-1 | C34: Hong | D34: Chi-Shing Jeff Hong | E34: National Park Foundation
A35: 28 | B35: 28-2 | D35: Shu-Hua Hong | E35: Banner Bank | F35: BOA
A36: 29 | B36: 29 | C36: Fine | D36: Shirley Fine范媽媽
A37: 30 | B37: 30 | C37: Yang | D37: Kaiwen Yang(Shan Hong Kaiwen) | E37: Chase
A38: 31 | B38: 31 | C38: Li | D38: JianQing Li建清 | E38: Bank of America
A39: 32 | B39: 32 | C39: Li | D39: Kevin L. Li | E39: Bank of America
A40: 33 | B40: 33 | C40: Li | D40: Ming C Li | E40: Bank of America
A41: 34 | B41: 34 | C41: x | D41: x | E41: x
...

Sheet 各月累計
C1: 2026奉獻
C2: 姓名 及 編號 | E2: 月份
C3: 加總 - 奉獻金額 | E3: 欄標籤
C4: 列標籤 | D4: 姓名 | E4: 1 | F4: 2 | G4: 3 | H4: 4 | I4: 5 | J4: 6 | K4: 總計
C5: 2 | D5: 喬阿姨Yen Pin Liu Chiao | G5: 600 | J5: 300 | K5: 900
C6: 6 | D6: Joseph Wu&Mei Chen | H6: 3000 | K6: 3000
C7: 7 | D7: 林敏雄Mr.&Mrs. Min-Shyong Lin | G7: 1000 | J7: 1000 | K7: 2000
C8: 8 | D8: Christopher Liu Pamela Yu Liu | E8: 400 | F8: 600 | G8: 1000 | H8: 800 | I8: 1000 | J8: 400 | K8: 4200
C9: 9 | D9: Min Deng鄧敏 Sandy | E9: 40 | F9: 40 | G9: 60 | H9: 60 | I9: 40 | J9: 60 | K9: 300
C10: 10 | D10: Yu Y Kang, Lie Chang Zhu | E10: 100 | F10: 100 | H10: 100 | I10: 50 | J10: 100 | K10: 450
C11: 11 | D11: Yu Mei Feng馮俞梅 | E11: 300 | F11: 300 | G11: 300 | H11: 100 | I11: 200 | J11: 300 | K11: 1500
C12: 12 | D12: Yu Hui Zhao趙宇輝 Yu Fei | F12: 100 | G12: 100 | H12: 100 | I12: 100 | J12: 200 | K12: 600
C13: 13 | D13: Ed &Allison Lee | E13: 100 | F13: 100 | G13: 400 | H13: 200 | I13: 200 | J13: 400 | K13: 1400
C14: 17 | D14: YU Ching Cheung天香/張譽馨 | E14: 272 | K14: 272
C15: 18 | D15: Yan Cheng程雁 | E15: 600 | F15: 700 | G15: 800 | H15: 600 | I15: 700 | J15: 700 | K15: 4100
C16: 19 | D16: Frank T. Chui | J16: 1000 | K16: 1000
C17: 20 | D17: 不具名 | E17: 2538.07 | F17: 588 | G17: 240 | H17: 163 | I17: 301 | J17: 79.8 | K17: 3909.87
C18: 25 | D18: 胡穎Hu Ying | G18: 200 | J18: 100 | K18: 300
C19: 26 | D19: Yvonne Chi-Ping Lan & Ming Lei Yeh | I19: 100 | J19: 500 | K19: 600
C20: 27 | D20: Sylvia Fine小元Charles | E20: 50 | I20: 100 | K20: 150
C21: 40 | D21: Suk Kuen Chan Lo Pastor Rainbow | G21: 100 | H21: 100 | I21: 100 | K21: 300
C22: 41 | D22: 王思旭 Sixu Wang(王悅玲) | E22: 400 | F22: 400 | G22: 200 | I22: 500 | J22: 300 | K22: 1800
C23: 42 | D23: Xia Lian Zhang張夏蓮 | H23: 100 | K23: 100
C24: 45 | D24: Dong Fang Li李東方 | E24: 30 | G24: 9 | I24: 9 | K24: 48
C25: 46 | D25: Liya Xia | G25: 200 | I25: 50 | J25: 200 | K25: 450
C26: 47 | D26: Hong Wang王宏 | G26: 400 | H26: 600 | I26: 400 | J26: 400 | K26: 1800
C27: 120 | D27: Xing Chen Lu-Michell | E27: 100 | K27: 100
D28: Jing | F28: 7.29 | K28: 7.29
D29: Qj Qin Pan(QQ Healing Message) | G29: 120 | K29: 120
D30: 黃小紅 | I30: 150 | K30: 150
D31: Wei Yan Hua | I31: 1000 | K31: 1000
D32: 盧瑾 | J32: 65 | K32: 65
C33: 17-2 | D33: 劉珈因Lau Ka Yan(Renee) | F33: 100 | G33: 200 | H33: 200 | I33: 200 | J33: 100 | K33: 800
C34: 40-2 | D34: Hung-Ben David Lo | G34: 100 | K34: 100
C35: 總計 | E35: 4930.07 | F35: 3035.29 | G35: 6029 | H35: 6123 | I35: 5200 | J35: 6204.8 | K35: 31522.16
E43: + | F43: v | G43: - | H43: + | I43: v | J43: - | K43: + | L43: - | M43: + | N43: + | O43: -
E44: 1750(12/29奉獻) | G44: 679(3/30奉獻) | H44: 679(3/30奉獻) | J44: 923(6/28奉獻) | K44: 923(6/28奉獻) | L44: 832(8/31奉獻) | M44: 832(8/31奉獻) | N44: 200(9/28奉獻) | O44: 798(11/30奉獻)
E45: + | G45: = | H45: = | J45: = | K45: = | L45: = | M45: - | N45: +
E46: 5000(12/31奉獻) | M46: 200(9/28奉獻) | N46: 2500美沂還款
E47: = | M47: = | N47: = | O47: =
...

Sheet 樞紐分析
B1: 信望愛教會
B2: 2026年奉獻徵信
B3: 月份 | C3: (全部)
B4: 週次 | C4: (全部)
G5: Stephen & Hsin-Ju Shih(Amy) | I5: 20710 Bending Pines Ln, Spring, TX77379
B6: 加總 - 奉獻金額 | D6: 欄標籤
B7: 列標籤 | C7: 姓名 | D7: 主日奉獻 | E7: 什一奉獻 | F7: 總計
B8: 2 | C8: 喬阿姨Yen Pin Liu Chiao | D8: 900 | F8: 900
B9: 6 | C9: Joseph Wu&Mei Chen | D9: 3000 | F9: 3000
B10: 7 | C10: 林敏雄Mr.&Mrs. Min-Shyong Lin | D10: 2000 | F10: 2000
B11: 8 | C11: Christopher Liu Pamela Yu Liu | D11: 4200 | F11: 4200
B12: 9 | C12: Min Deng鄧敏 Sandy | D12: 300 | F12: 300
B13: 10 | C13: Yu Y Kang, Lie Chang Zhu | D13: 450 | F13: 450
B14: 11 | C14: Yu Mei Feng馮俞梅 | D14: 1500 | F14: 1500
B15: 12 | C15: Yu Hui Zhao趙宇輝 Yu Fei | D15: 600 | F15: 600
B16: 13 | C16: Ed &Allison Lee | D16: 1400 | F16: 1400
B17: 17 | C17: YU Ching Cheung天香/張譽馨 | D17: 272 | F17: 272
B18: 18 | C18: Yan Cheng程雁 | D18: 4100 | F18: 4100
B19: 19 | C19: Frank T. Chui | D19: 1000 | F19: 1000
B20: 20 | C20: 不具名 | D20: 1909.87 | E20: 2000 | F20: 3909.87
B21: 25 | C21: 胡穎Hu Ying | D21: 300 | F21: 300
B22: 26 | C22: Yvonne Chi-Ping Lan & Ming Lei Yeh | D22: 600 | F22: 600
B23: 27 | C23: Sylvia Fine小元Charles | D23: 150 | F23: 150
B24: 40 | C24: Suk Kuen Chan Lo Pastor Rainbow | D24: 300 | F24: 300
B25: 41 | C25: 王思旭 Sixu Wang(王悅玲) | D25: 1800 | F25: 1800
B26: 42 | C26: Xia Lian Zhang張夏蓮 | D26: 100 | F26: 100
B27: 45 | C27: Dong Fang Li李東方 | D27: 48 | F27: 48
B28: 46 | C28: Liya Xia | D28: 450 | F28: 450
B29: 47 | C29: Hong Wang王宏 | D29: 1800 | F29: 1800
B30: 120 | C30: Xing Chen Lu-Michell | D30: 100 | F30: 100
C31: Jing | D31: 7.29 | F31: 7.29
C32: Qj Qin Pan(QQ Healing Message) | D32: 120 | F32: 120
C33: 黃小紅 | D33: 150 | F33: 150
C34: Wei Yan Hua | D34: 1000 | F34: 1000
C35: 盧瑾 | D35: 65 | F35: 65
B36: 總計 | D36: 28622.16 | E36: 2000 | F36: 30622.16

Sheet 一月份
B2: 信望愛教會
B3: 2026年奉獻徵信
B4: 月份 | C4: 1
B5: 週次 | C5: (全部)
B7: 加總 - 奉獻金額 | D7: 欄標籤
B8: 列標籤 | C8: 姓名 | D8: 主日奉獻 | E8: (空白) | F8: 什一奉獻 | G8: 總計
B9: 8 | C9: Christopher Liu Pamela Yu Liu | D9: 400 | G9: 400
B10: 9 | C10: Min Deng鄧敏 Sandy | D10: 40 | G10: 40
B11: 10 | C11: Yu Y Kang, Lie Chang Zhu | D11: 100 | G11: 100
B12: 11 | C12: Yu Mei Feng馮俞梅 | D12: 300 | G12: 300
B13: 13 | C13: Ed &Allison Lee | D13: 100 | G13: 100
B14: 17 | C14: YU Ching Cheung天香/張譽馨 | D14: 272 | G14: 272
B15: 18 | C15: Yan Cheng程雁 | D15: 600 | G15: 600
B16: 20 | C16: 不具名 | D16: 538.07 | F16: 2000 | G16: 2538.07
B17: 27 | C17: Sylvia Fine小元Charles | D17: 50 | G17: 50
B18: 41 | C18: 王思旭 Sixu Wang(王悅玲) | D18: 400 | G18: 400
B19: 45 | C19: Dong Fang Li李東方 | D19: 30 | G19: 30
B20: 120 | C20: Xing Chen Lu-Michell | D20: 100 | G20: 100
B21: (空白) | C21: (空白)
B22: 總計 | D22: 2930.07 | F22: 2000 | G22: 4930.07

Sheet 二月份
C3: 信望愛教會
C4: 2026年奉獻徵信
C5: 月份 | D5: 2
C6: 週次 | D6: (全部)
C8: 加總 - 奉獻金額 | E8: 欄標籤
C9: 列標籤 | D9: 姓名 | E9: 主日奉獻 | F9: 總計
C10: 8 | D10: Christopher Liu Pamela Yu Liu | E10: 600 | F10: 600
C11: 9 | D11: Min Deng鄧敏 Sandy | E11: 40 | F11: 40
C12: 10 | D12: Yu Y Kang, Lie Chang Zhu | E12: 100 | F12: 100
C13: 11 | D13: Yu Mei Feng馮俞梅 | E13: 300 | F13: 300
C14: 12 | D14: Yu Hui Zhao趙宇輝 Yu Fei | E14: 100 | F14: 100
C15: 13 | D15: Ed &Allison Lee | E15: 100 | F15: 100
C16: 18 | D16: Yan Cheng程雁 | E16: 700 | F16: 700
C17: 20 | D17: 不具名 | E17: 588 | F17: 588
C18: 41 | D18: 王思旭 Sixu Wang(王悅玲) | E18: 400 | F18: 400
C19: 120 | D19: Jing | E19: 7.29 | F19: 7.29
C20: 17-2 | D20: 劉珈因Lau Ka Yan(Renee) | E20: 100 | F20: 100
C21: 總計 | E21: 3035.29 | F21: 3035.29

Sheet 三月份
C4: 信望愛教會
C5: 2026年奉獻徵信
C6: 月份 | D6: 3
C7: 週次 | D7: (全部)
C9: 加總 - 奉獻金額 | E9: 欄標籤
C10: 列標籤 | D10: 姓名 | E10: 主日奉獻 | F10: 總計
C11: 2 | D11: 喬阿姨Yen Pin Liu Chiao | E11: 600 | F11: 600
C12: 7 | D12: 林敏雄Mr.&Mrs. Min-Shyong Lin | E12: 1000 | F12: 1000
C13: 8 | D13: Christopher Liu Pamela Yu Liu | E13: 1000 | F13: 1000
C14: 9 | D14: Min Deng鄧敏 Sandy | E14: 60 | F14: 60
C15: 11 | D15: Yu Mei Feng馮俞梅 | E15: 300 | F15: 300
C16: 12 | D16: Yu Hui Zhao趙宇輝 Yu Fei | E16: 100 | F16: 100
C17: 13 | D17: Ed &Allison Lee | E17: 400 | F17: 400
C18: 18 | D18: Yan Cheng程雁 | E18: 800 | F18: 800
C19: 20 | D19: 不具名 | E19: 240 | F19: 240
C20: 25 | D20: 胡穎Hu Ying | E20: 200 | F20: 200
C21: 40 | D21: Suk Kuen Chan Lo Pastor Rainbow | E21: 100 | F21: 100
C22: 41 | D22: 王思旭 Sixu Wang(王悅玲) | E22: 200 | F22: 200
... C26: 120 | D26: Qj Qin Pan(QQ Healing Message) | E26: 120 | F26: 120
C27: 17-2 | D27: 劉珈因Lau Ka Yan(Renee) | E27: 200 | F27: 200
C28: 40-2 | D28: Hung-Ben David Lo | E28: 100 | F28: 100
C29: 總計 | E29: 6029 | F29: 6029

Sheet 四月份
B1: 信望愛教會
B2: 2026年奉獻徵信
B3: 月份 | C3: 4
B4: 週次 | C4: (全部)
B6: 加總 - 奉獻金額 | D6: 欄標籤
B7: 列標籤 | C7: 姓名 | D7: 主日奉獻 | E7: 總計 | G7: =姓名檔!F65 -> Stephen & Hsin-Ju Shih(Amy) | I7: 20710 Bending Pines Ln, Spring, TX77379
B8: 6 | C8: Joseph Wu&Mei Chen | D8: 3000 | E8: 3000
B9: 8 | C9: Christopher Liu Pamela Yu Liu | D9: 800 | E9: 800
B10: 9 | C10: Min Deng鄧敏 Sandy | D10: 60 | E10: 60
B11: 10 | C11: Yu Y Kang, Lie Chang Zhu | D11: 100 | E11: 100
B12: 11 | C12: Yu Mei Feng馮俞梅 | D12: 100 | E12: 100
B13: 12 | C13: Yu Hui Zhao趙宇輝 Yu Fei | D13: 100 | E13: 100
B14: 13 | C14: Ed &Allison Lee | D14: 200 | E14: 200
B15: 18 | C15: Yan Cheng程雁 | D15: 600 | E15: 600
B16: 20 | C16: 不具名 | D16: 163 | E16: 163
B17: 40 | C17: Suk Kuen Chan Lo Pastor Rainbow | D17: 100 | E17: 100
B18: 42 | C18: Xia Lian Zhang張夏蓮 | D18: 100 | E18: 100
B19: 總計 | D19: 5323 | E19: 5323

Sheet 五月份
B2: 信望愛教會
B3: 2026年奉獻徵信
B4: 月份 | C4: 5
B5: 週次 | C5: (全部)
B7: 加總 - 奉獻金額 | D7: 欄標籤
B8: 列標籤 | C8: 姓名 | D8: 主日奉獻 | E8: 總計
B9: 8 | C9: Christopher Liu Pamela Yu Liu | D9: 1000 | E9: 1000
B10: 9 | C10: Min Deng鄧敏 Sandy | D10: 40 | E10: 40
B11: 10 | C11: Yu Y Kang, Lie Chang Zhu | D11: 50 | E11: 50
B12: 11 | C12: Yu Mei Feng馮俞梅 | D12: 200 | E12: 200
B13: 12 | C13: Yu Hui Zhao趙宇輝 Yu Fei | D13: 100 | E13: 100
B14: 13 | C14: Ed &Allison Lee | D14: 200 | E14: 200
B15: 18 | C15: Yan Cheng程雁 | D15: 700 | E15: 700
B16: 20 | C16: 不具名 | D16: 301 | E16: 301
B17: 26 | C17: Yvonne Chi-Ping Lan & Ming Lei Yeh | D17: 100 | E17: 100
B18: 27 | C18: Sylvia Fine小元Charles | D18: 100 | E18: 100
B19: 40 | C19: Suk Kuen Chan Lo Pastor Rainbow | D19: 100 | E19: 100
B20: 41 | C20: 王思旭 Sixu Wang(王悅玲) | D20: 500 | E20: 500
... B24: 120 | C24: 黃小紅 | D24: 150 | E24: 150
C25: Wei Yan Hua | D25: 1000 | E25: 1000
B26: 總計 | D26: 5000 | E26: 5000

Sheet 六月份
B1: 信望愛教會
B2: 2026年奉獻徵信
B3: 月份 | C3: 6
B4: 週次 | C4: (全部)
B6: 加總 - 奉獻金額 | D6: 欄標籤
B7: 列標籤 | C7: 姓名 | D7: 主日奉獻 | E7: 總計
B8: 2 | C8: 喬阿姨Yen Pin Liu Chiao | D8: 300 | E8: 300
B9: 7 | C9: 林敏雄Mr.&Mrs. Min-Shyong Lin | D9: 1000 | E9: 1000
B10: 8 | C10: Christopher Liu Pamela Yu Liu | D10: 400 | E10: 400
B11: 9 | C11: Min Deng鄧敏 Sandy | D11: 60 | E11: 60
B12: 10 | C12: Yu Y Kang, Lie Chang Zhu | D12: 100 | E12: 100
B13: 11 | C13: Yu Mei Feng馮俞梅 | D13: 300 | E13: 300
B14: 12 | C14: Yu Hui Zhao趙宇輝 Yu Fei | D14: 200 | E14: 200
B15: 13 | C15: Ed &Allison Lee | D15: 400 | E15: 400
B16: 18 | C16: Yan Cheng程雁 | D16: 700 | E16: 700
B17: 19 | C17: Frank T. Chui | D17: 1000 | E17: 1000
B18: 20 | C18: 不具名 | D18: 79.8 | E18: 79.8
B19: 25 | C19: 胡穎Hu Ying | D19: 100 | E19: 100
... B24: 120 | C24: 盧瑾 | D24: 65 | E24: 65
B25: 總計 | D25: 6104.8 | E25: 6104.8

Sheet 七月份
B1: 信望愛教會
B2: 2026年奉獻徵信
B3: 月份 | C3: 7
B4: 週次 | C4: (全部)
B6: 加總 - 奉獻金額 | D6: 欄標籤
B7: 列標籤 | C7: 姓名 | D7: 總計
B8: 總計

Sheet 八月份
B2: 信望愛教會
B3: 2026年奉獻徵信
B4: 月份 | C4: 8
B5: 週次 | C5: (全部)
B7: 加總 - 奉獻金額 | D7: 欄標籤
B8: 列標籤 | C8: 姓名 | D8: 主日奉獻 | E8: 總計
B9: (空白) | C9: #N/A
B10: 總計

Sheet 九月份
B2: 信望愛教會
B3: 2026年奉獻徵信
B4: 月份 | C4: 9
B5: 週次 | C5: (全部)
B7: 加總 - 奉獻金額 | D7: 欄標籤
B8: 列標籤 | C8: 姓名 | D8: 主日奉獻 | E8: 總計
B9: (空白) | C9: #N/A
B10: 總計

Sheet 十月份
B1: 信望愛教會
B2: 2026年奉獻徵信
B3: 月份 | C3: 10
B4: 週次 | C4: (全部)
B6: 加總 - 奉獻金額 | D6: 欄標籤
B7: 列標籤 | C7: 姓名 | D7: 主日奉獻 | E7: (空白) | F7: 其他收入 | G7: 總計
B8: (空白) | C8: #N/A
C9: (空白)
B10: 總計

Sheet 十一月份
B1: 信望愛教會
B2: 2026年奉獻徵信
B3: 月份 | C3: 11
B4: 週次 | C4: (全部)
B6: 加總 - 奉獻金額 | D6: 欄標籤
B7: 列標籤 | C7: 姓名 | D7: 主日奉獻 | E7: 總計
B8: (空白) | C8: #N/A
B9: 總計

Sheet 十二月份
B1: 信望愛教會
B2: 2026年奉獻徵信
B3: 月份 | C3: 12
B4: 週次 | C4: (全部)
B6: 加總 - 奉獻金額 | D6: 欄標籤
B7: 列標籤 | C7: 姓名 | D7: 主日奉獻 | E7: 總計
B8: (空白) | C8: #N/A
B9: 總計
